Workbook

Sheet Rankings
A1: Ranked opportunities - best entry, most expected growth, soonest setup
A2: Score 0-100 (weights on the Inputs tab). Growth = upside to the price target (12-month analyst horizon). Entry = upside vs. room down to the review level at today's price. Timing = pre-breakout chart score. A rank is a research order, not a buy order: check the STATUS, news and wash-sale locks.
A4: Rank | B4: Symbol | C4: Source | D4: SCORE | E4: Price | F4: Target | G4: Upside | H4: Review Level | I4: Room to Review | J4: Reward : Risk | K4: Setup Score | L4: Agreement | M4: Status
A5: 1 | B5: =IFERROR(INDEX('Rank Calc'!$A$5:$A$53,MATCH($A5,'Rank Calc'!$P$5:$P$53,0)),"") | C5: =IFERROR(INDEX('Rank Calc'!$B$5:$B$53,MATCH($A5,'Rank Calc'!$P$5:$P$53,0)),"") | D5: =IFERROR(INDEX('Rank Calc'!$O$5:$O$53,MATCH($A5,'Rank Calc'!$P$5:$P$53,0)),"") | E5: =IFERROR(INDEX('Rank Calc'!$C$5:$C$53,MATCH($A5,'Rank Calc'!$P$5:$P$53,0)),"") | F5: =IFERROR(INDEX('Rank Calc'!$D$5:$D$53,MATCH($A5,'Rank Calc'!$P$5:$P$53,0)),"") | G5: =IFERROR(INDEX('Rank Calc'!$I$5:$I$53,MATCH($A5,'Rank Calc'!$P$5:$P$53,0)),"") | H5: =IFERROR(INDEX('Rank Calc'!$E$5:$E$53,MATCH($A5,'Rank Calc'!$P$5:$P$53,0)),"") | I5: =IFERROR(INDEX('Rank Calc'!$J$5:$J$53,MATCH($A5,'Rank Calc'!$P$5:$P$53,0)),"") | J5: =IFERROR(INDEX('Rank Calc'!$K$5:$K$53,MATCH($A5,'Rank Calc'!$P$5:$P$53,0)),"") | K5: =IFERROR(INDEX('Rank Calc'!$G$5:$G$53,MATCH($A5,'Rank Calc'!$P$5:$P$53,0)),"") | L5: =IFERROR(INDEX('Rank Calc'!$F$5:$F$53,MATCH($A5,'Rank Calc'!$P$5:$P$53,0)),"") | M5: =IFERROR(INDEX('Rank Calc'!$H$5:$H$53,MATCH($A5,'Rank Calc'!$P$5:$P$53,0)),"")
A6: 2 | B6: =IFERROR(INDEX('Rank Calc'!$A$5:$A$53,MATCH($A6,'Rank Calc'!$P$5:$P$53,0)),"") | C6: =IFERROR(INDEX('Rank Calc'!$B$5:$B$53,MATCH($A6,'Rank Calc'!$P$5:$P$53,0)),"") | D6: =IFERROR(INDEX('Rank Calc'!$O$5:$O$53,MATCH($A6,'Rank Calc'!$P$5:$P$53,0)),"") | E6: =IFERROR(INDEX('Rank Calc'!$C$5:$C$53,MATCH($A6,'Rank Calc'!$P$5:$P$53,0)),"") | F6: =IFERROR(INDEX('Rank Calc'!$D$5:$D$53,MATCH($A6,'Rank Calc'!$P$5:$P$53,0)),"") | G6: =IFERROR(INDEX('Rank Calc'!$I$5:$I$53,MATCH($A6,'Rank Calc'!$P$5:$P$53,0)),"") | H6: =IFERROR(INDEX('Rank Calc'!$E$5:$E$53,MATCH($A6,'Rank Calc'!$P$5:$P$53,0)),"") | I6: =IFERROR(INDEX('Rank Calc'!$J$5:$J$53,MATCH($A6,'Rank Calc'!$P$5:$P$53,0)),"") | J6: =IFERROR(INDEX('Rank Calc'!$K$5:$K$53,MATCH($A6,'Rank Calc'!$P$5:$P$53,0)),"") | K6: =IFERROR(INDEX('Rank Calc'!$G$5:$G$53,MATCH($A6,'Rank Calc'!$P$5:$P$53,0)),"") | L6: =IFERROR(INDEX('Rank Calc'!$F$5:$F$53,MATCH($A6,'Rank Calc'!$P$5:$P$53,0)),"") | M6: =IFERROR(INDEX('Rank Calc'!$H$5:$H$53,MATCH($A6,'Rank Calc'!$P$5:$P$53,0)),"")
A7: 3 | B7: =IFERROR(INDEX('Rank Calc'!$A$5:$A$53,MATCH($A7,'Rank Calc'!$P$5:$P$53,0)),"") | C7: =IFERROR(INDEX('Rank Calc'!$B$5:$B$53,MATCH($A7,'Rank Calc'!$P$5:$P$53,0)),"") | D7: =IFERROR(INDEX('Rank Calc'!$O$5:$O$53,MATCH($A7,'Rank Calc'!$P$5:$P$53,0)),"") | E7: =IFERROR(INDEX('Rank Calc'!$C$5:$C$53,MATCH($A7,'Rank Calc'!$P$5:$P$53,0)),"") | F7: =IFERROR(INDEX('Rank Calc'!$D$5:$D$53,MATCH($A7,'Rank Calc'!$P$5:$P$53,0)),"") | G7: =IFERROR(INDEX('Rank Calc'!$I$5:$I$53,MATCH($A7,'Rank Calc'!$P$5:$P$53,0)),"") | H7: =IFERROR(INDEX('Rank Calc'!$E$5:$E$53,MATCH($A7,'Rank Calc'!$P$5:$P$53,0)),"") | I7: =IFERROR(INDEX('Rank Calc'!$J$5:$J$53,MATCH($A7,'Rank Calc'!$P$5:$P$53,0)),"") | J7: =IFERROR(INDEX('Rank Calc'!$K$5:$K$53,MATCH($A7,'Rank Calc'!$P$5:$P$53,0)),"") | K7: =IFERROR(INDEX('Rank Calc'!$G$5:$G$53,MATCH($A7,'Rank Calc'!$P$5:$P$53,0)),"") | L7: =IFERROR(INDEX('Rank Calc'!$F$5:$F$53,MATCH($A7,'Rank Calc'!$P$5:$P$53,0)),"") | M7: =IFERROR(INDEX('Rank Calc'!$H$5:$H$53,MATCH($A7,'Rank Calc'!$P$5:$P$53,0)),"")
A8: 4 | B8: =IFERROR(INDEX('Rank Calc'!$A$5:$A$53,MATCH($A8,'Rank Calc'!$P$5:$P$53,0)),"") | C8: =IFERROR(INDEX('Rank Calc'!$B$5:$B$53,MATCH($A8,'Rank Calc'!$P$5:$P$53,0)),"") | D8: =IFERROR(INDEX('Rank Calc'!$O$5:$O$53,MATCH($A8,'Rank Calc'!$P$5:$P$53,0)),"") | E8: =IFERROR(INDEX('Rank Calc'!$C$5:$C$53,MATCH($A8,'Rank Calc'!$P$5:$P$53,0)),"") | F8: =IFERROR(INDEX('Rank Calc'!$D$5:$D$53,MATCH($A8,'Rank Calc'!$P$5:$P$53,0)),"") | G8: =IFERROR(INDEX('Rank Calc'!$I$5:$I$53,MATCH($A8,'Rank Calc'!$P$5:$P$53,0)),"") | H8: =IFERROR(INDEX('Rank Calc'!$E$5:$E$53,MATCH($A8,'Rank Calc'!$P$5:$P$53,0)),"") | I8: =IFERROR(INDEX('Rank Calc'!$J$5:$J$53,MATCH($A8,'Rank Calc'!$P$5:$P$53,0)),"") | J8: =IFERROR(INDEX('Rank Calc'!$K$5:$K$53,MATCH($A8,'Rank Calc'!$P$5:$P$53,0)),"") | K8: =IFERROR(INDEX('Rank Calc'!$G$5:$G$53,MATCH($A8,'Rank Calc'!$P$5:$P$53,0)),"") | L8: =IFERROR(INDEX('Rank Calc'!$F$5:$F$53,MATCH($A8,'Rank Calc'!$P$5:$P$53,0)),"") | M8: =IFERROR(INDEX('Rank Calc'!$H$5:$H$53,MATCH($A8,'Rank Calc'!$P$5:$P$53,0)),"")
A9: 5 | B9: =IFERROR(INDEX('Rank Calc'!$A$5:$A$53,MATCH($A9,'Rank Calc'!$P$5:$P$53,0)),"") | C9: =IFERROR(INDEX('Rank Calc'!$B$5:$B$53,MATCH($A9,'Rank Calc'!$P$5:$P$53,0)),"") | D9: =IFERROR(INDEX('Rank Calc'!$O$5:$O$53,MATCH($A9,'Rank Calc'!$P$5:$P$53,0)),"") | E9: =IFERROR(INDEX('Rank Calc'!$C$5:$C$53,MATCH($A9,'Rank Calc'!$P$5:$P$53,0)),"") | F9: =IFERROR(INDEX('Rank Calc'!$D$5:$D$53,MATCH($A9,'Rank Calc'!$P$5:$P$53,0)),"") | G9: =IFERROR(INDEX('Rank Calc'!$I$5:$I$53,MATCH($A9,'Rank Calc'!$P$5:$P$53,0)),"") | H9: =IFERROR(INDEX('Rank Calc'!$E$5:$E$53,MATCH($A9,'Rank Calc'!$P$5:$P$53,0)),"") | I9: =IFERROR(INDEX('Rank Calc'!$J$5:$J$53,MATCH($A9,'Rank Calc'!$P$5:$P$53,0)),"") | J9: =IFERROR(INDEX('Rank Calc'!$K$5:$K$53,MATCH($A9,'Rank Calc'!$P$5:$P$53,0)),"") | K9: =IFERROR(INDEX('Rank Calc'!$G$5:$G$53,MATCH($A9,'Rank Calc'!$P$5:$P$53,0)),"") | L9: =IFERROR(INDEX('Rank Calc'!$F$5:$F$53,MATCH($A9,'Rank Calc'!$P$5:$P$53,0)),"") | M9: =IFERROR(INDEX('Rank Calc'!$H$5:$H$53,MATCH($A9,'Rank Calc'!$P$5:$P$53,0)),"")
A10: 6 | B10: =IFERROR(INDEX('Rank Calc'!$A$5:$A$53,MATCH($A10,'Rank Calc'!$P$5:$P$53,0)),"") | C10: =IFERROR(INDEX('Rank Calc'!$B$5:$B$53,MATCH($A10,'Rank Calc'!$P$5:$P$53,0)),"") | D10: =IFERROR(INDEX('Rank Calc'!$O$5:$O$53,MATCH($A10,'Rank Calc'!$P$5:$P$53,0)),"") | E10: =IFERROR(INDEX('Rank Calc'!$C$5:$C$53,MATCH($A10,'Rank Calc'!$P$5:$P$53,0)),"") | F10: =IFERROR(INDEX('Rank Calc'!$D$5:$D$53,MATCH($A10,'Rank Calc'!$P$5:$P$53,0)),"") | G10: =IFERROR(INDEX('Rank Calc'!$I$5:$I$53,MATCH($A10,'Rank Calc'!$P$5:$P$53,0)),"") | H10: =IFERROR(INDEX('Rank Calc'!$E$5:$E$53,MATCH($A10,'Rank Calc'!$P$5:$P$53,0)),"") | I10: =IFERROR(INDEX('Rank Calc'!$J$5:$J$53,MATCH($A10,'Rank Calc'!$P$5:$P$53,0)),"") | J10: =IFERROR(INDEX('Rank Calc'!$K$5:$K$53,MATCH($A10,'Rank Calc'!$P$5:$P$53,0)),"") | K10: =IFERROR(INDEX('Rank Calc'!$G$5:$G$53,MATCH($A10,'Rank Calc'!$P$5:$P$53,0)),"") | L10: =IFERROR(INDEX('Rank Calc'!$F$5:$F$53,MATCH($A10,'Rank Calc'!$P$5:$P$53,0)),"") | M10: =IFERROR(INDEX('Rank Calc'!$H$5:$H$53,MATCH($A10,'Rank Calc'!$P$5:$P$53,0)),"")
A11: 7 | B11: =IFERROR(INDEX('Rank Calc'!$A$5:$A$53,MATCH($A11,'Rank Calc'!$P$5:$P$53,0)),"") | C11: =IFERROR(INDEX('Rank Calc'!$B$5:$B$53,MATCH($A11,'Rank Calc'!$P$5:$P$53,0)),"") | D11: =IFERROR(INDEX('Rank Calc'!$O$5:$O$53,MATCH($A11,'Rank Calc'!$P$5:$P$53,0)),"") | E11: =IFERROR(INDEX('Rank Calc'!$C$5:$C$53,MATCH($A11,'Rank Calc'!$P$5:$P$53,0)),"") | F11: =IFERROR(INDEX('Rank Calc'!$D$5:$D$53,MATCH($A11,'Rank Calc'!$P$5:$P$53,0)),"") | G11: =IFERROR(INDEX('Rank Calc'!$I$5:$I$53,MATCH($A11,'Rank Calc'!$P$5:$P$53,0)),"") | H11: =IFERROR(INDEX('Rank Calc'!$E$5:$E$53,MATCH($A11,'Rank Calc'!$P$5:$P$53,0)),"") | I11: =IFERROR(INDEX('Rank Calc'!$J$5:$J$53,MATCH($A11,'Rank Calc'!$P$5:$P$53,0)),"") | J11: =IFERROR(INDEX('Rank Calc'!$K$5:$K$53,MATCH($A11,'Rank Calc'!$P$5:$P$53,0)),"") | K11: =IFERROR(INDEX('Rank Calc'!$G$5:$G$53,MATCH($A11,'Rank Calc'!$P$5:$P$53,0)),"") | L11: =IFERROR(INDEX('Rank Calc'!$F$5:$F$53,MATCH($A11,'Rank Calc'!$P$5:$P$53,0)),"") | M11: =IFERROR(INDEX('Rank Calc'!$H$5:$H$53,MATCH($A11,'Rank Calc'!$P$5:$P$53,0)),"")
A12: 8 | B12: =IFERROR(INDEX('Rank Calc'!$A$5:$A$53,MATCH($A12,'Rank Calc'!$P$5:$P$53,0)),"") | C12: =IFERROR(INDEX('Rank Calc'!$B$5:$B$53,MATCH($A12,'Rank Calc'!$P$5:$P$53,0)),"") | D12: =IFERROR(INDEX('Rank Calc'!$O$5:$O$53,MATCH($A12,'Rank Calc'!$P$5:$P$53,0)),"") | E12: =IFERROR(INDEX('Rank Calc'!$C$5:$C$53,MATCH($A12,'Rank Calc'!$P$5:$P$53,0)),"") | F12: =IFERROR(INDEX('Rank Calc'!$D$5:$D$53,MATCH($A12,'Rank Calc'!$P$5:$P$53,0)),"") | G12: =IFERROR(INDEX('Rank Calc'!$I$5:$I$53,MATCH($A12,'Rank Calc'!$P$5:$P$53,0)),"") | H12: =IFERROR(INDEX('Rank Calc'!$E$5:$E$53,MATCH($A12,'Rank Calc'!$P$5:$P$53,0)),"") | I12: =IFERROR(INDEX('Rank Calc'!$J$5:$J$53,MATCH($A12,'Rank Calc'!$P$5:$P$53,0)),"") | J12: =IFERROR(INDEX('Rank Calc'!$K$5:$K$53,MATCH($A12,'Rank Calc'!$P$5:$P$53,0)),"") | K12: =IFERROR(INDEX('Rank Calc'!$G$5:$G$53,MATCH($A12,'Rank Calc'!$P$5:$P$53,0)),"") | L12: =IFERROR(INDEX('Rank Calc'!$F$5:$F$53,MATCH($A12,'Rank Calc'!$P$5:$P$53,0)),"") | M12: =IFERROR(INDEX('Rank Calc'!$H$5:$H$53,MATCH($A12,'Rank Calc'!$P$5:$P$53,0)),"")
A13: 9 | B13: =IFERROR(INDEX('Rank Calc'!$A$5:$A$53,MATCH($A13,'Rank Calc'!$P$5:$P$53,0)),"") | C13: =IFERROR(INDEX('Rank Calc'!$B$5:$B$53,MATCH($A13,'Rank Calc'!$P$5:$P$53,0)),"") | D13: =IFERROR(INDEX('Rank Calc'!$O$5:$O$53,MATCH($A13,'Rank Calc'!$P$5:$P$53,0)),"") | E13: =IFERROR(INDEX('Rank Calc'!$C$5:$C$53,MATCH($A13,'Rank Calc'!$P$5:$P$53,0)),"") | F13: =IFERROR(INDEX('Rank Calc'!$D$5:$D$53,MATCH($A13,'Rank Calc'!$P$5:$P$53,0)),"") | G13: =IFERROR(INDEX('Rank Calc'!$I$5:$I$53,MATCH($A13,'Rank Calc'!$P$5:$P$53,0)),"") | H13: =IFERROR(INDEX('Rank Calc'!$E$5:$E$53,MATCH($A13,'Rank Calc'!$P$5:$P$53,0)),"") | I13: =IFERROR(INDEX('Rank Calc'!$J$5:$J$53,MATCH($A13,'Rank Calc'!$P$5:$P$53,0)),"") | J13: =IFERROR(INDEX('Rank Calc'!$K$5:$K$53,MATCH($A13,'Rank Calc'!$P$5:$P$53,0)),"") | K13: =IFERROR(INDEX('Rank Calc'!$G$5:$G$53,MATCH($A13,'Rank Calc'!$P$5:$P$53,0)),"") | L13: =IFERROR(INDEX('Rank Calc'!$F$5:$F$53,MATCH($A13,'Rank Calc'!$P$5:$P$53,0)),"") | M13: =IFERROR(INDEX('Rank Calc'!$H$5:$H$53,MATCH($A13,'Rank Calc'!$P$5:$P$53,0)),"")
A14: 10 | B14: =IFERROR(INDEX('Rank Calc'!$A$5:$A$53,MATCH($A14,'Rank Calc'!$P$5:$P$53,0)),"") | C14: =IFERROR(INDEX('Rank Calc'!$B$5:$B$53,MATCH($A14,'Rank Calc'!$P$5:$P$53,0)),"") | D14: =IFERROR(INDEX('Rank Calc'!$O$5:$O$53,MATCH($A14,'Rank Calc'!$P$5:$P$53,0)),"") | E14: =IFERROR(INDEX('Rank Calc'!$C$5:$C$53,MATCH($A14,'Rank Calc'!$P$5:$P$53,0)),"") | F14: =IFERROR(INDEX('Rank Calc'!$D$5:$D$53,MATCH($A14,'Rank Calc'!$P$5:$P$53,0)),"") | G14: =IFERROR(INDEX('Rank Calc'!$I$5:$I$53,MATCH($A14,'Rank Calc'!$P$5:$P$53,0)),"") | H14: =IFERROR(INDEX('Rank Calc'!$E$5:$E$53,MATCH($A14,'Rank Calc'!$P$5:$P$53,0)),"") | I14: =IFERROR(INDEX('Rank Calc'!$J$5:$J$53,MATCH($A14,'Rank Calc'!$P$5:$P$53,0)),"") | J14: =IFERROR(INDEX('Rank Calc'!$K$5:$K$53,MATCH($A14,'Rank Calc'!$P$5:$P$53,0)),"") | K14: =IFERROR(INDEX('Rank Calc'!$G$5:$G$53,MATCH($A14,'Rank Calc'!$P$5:$P$53,0)),"") | L14: =IFERROR(INDEX('Rank Calc'!$F$5:$F$53,MATCH($A14,'Rank Calc'!$P$5:$P$53,0)),"") | M14: =IFERROR(INDEX('Rank Calc'!$H$5:$H$53,MATCH($A14,'Rank Calc'!$P$5:$P$53,0)),"")
A15: 11 | B15: =IFERROR(INDEX('Rank Calc'!$A$5:$A$53,MATCH($A15,'Rank Calc'!$P$5:$P$53,0)),"") | C15: =IFERROR(INDEX('Rank Calc'!$B$5:$B$53,MATCH($A15,'Rank Calc'!$P$5:$P$53,0)),"") | D15: =IFERROR(INDEX('Rank Calc'!$O$5:$O$53,MATCH($A15,'Rank Calc'!$P$5:$P$53,0)),"") | E15: =IFERROR(INDEX('Rank Calc'!$C$5:$C$53,MATCH($A15,'Rank Calc'!$P$5:$P$53,0)),"") | F15: =IFERROR(INDEX('Rank Calc'!$D$5:$D$53,MATCH($A15,'Rank Calc'!$P$5:$P$53,0)),"") | G15: =IFERROR(INDEX('Rank Calc'!$I$5:$I$53,MATCH($A15,'Rank Calc'!$P$5:$P$53,0)),"") | H15: =IFERROR(INDEX('Rank Calc'!$E$5:$E$53,MATCH($A15,'Rank Calc'!$P$5:$P$53,0)),"") | I15: =IFERROR(INDEX('Rank Calc'!$J$5:$J$53,MATCH($A15,'Rank Calc'!$P$5:$P$53,0)),"") | J15: =IFERROR(INDEX('Rank Calc'!$K$5:$K$53,MATCH($A15,'Rank Calc'!$P$5:$P$53,0)),"") | K15: =IFERROR(INDEX('Rank Calc'!$G$5:$G$53,MATCH($A15,'Rank Calc'!$P$5:$P$53,0)),"") | L15: =IFERROR(INDEX('Rank Calc'!$F$5:$F$53,MATCH($A15,'Rank Calc'!$P$5:$P$53,0)),"") | M15: =IFERROR(INDEX('Rank Calc'!$H$5:$H$53,MATCH($A15,'Rank Calc'!$P$5:$P$53,0)),"")
A16: 12 | B16: =IFERROR(INDEX('Rank Calc'!$A$5:$A$53,MATCH($A16,'Rank Calc'!$P$5:$P$53,0)),"") | C16: =IFERROR(INDEX('Rank Calc'!$B$5:$B$53,MATCH($A16,'Rank Calc'!$P$5:$P$53,0)),"") | D16: =IFERROR(INDEX('Rank Calc'!$O$5:$O$53,MATCH($A16,'Rank Calc'!$P$5:$P$53,0)),"") | E16: =IFERROR(INDEX('Rank Calc'!$C$5:$C$53,MATCH($A16,'Rank Calc'!$P$5:$P$53,0)),"") | F16: =IFERROR(INDEX('Rank Calc'!$D$5:$D$53,MATCH($A16,'Rank Calc'!$P$5:$P$53,0)),"") | G16: =IFERROR(INDEX('Rank Calc'!$I$5:$I$53,MATCH($A16,'Rank Calc'!$P$5:$P$53,0)),"") | H16: =IFERROR(INDEX('Rank Calc'!$E$5:$E$53,MATCH($A16,'Rank Calc'!$P$5:$P$53,0)),"") | I16: =IFERROR(INDEX('Rank Calc'!$J$5:$J$53,MATCH($A16,'Rank Calc'!$P$5:$P$53,0)),"") | J16: =IFERROR(INDEX('Rank Calc'!$K$5:$K$53,MATCH($A16,'Rank Calc'!$P$5:$P$53,0)),"") | K16: =IFERROR(INDEX('Rank Calc'!$G$5:$G$53,MATCH($A16,'Rank Calc'!$P$5:$P$53,0)),"") | L16: =IFERROR(INDEX('Rank Calc'!$F$5:$F$53,MATCH($A16,'Rank Calc'!$P$5:$P$53,0)),"") | M16: =IFERROR(INDEX('Rank Calc'!$H$5:$H$53,MATCH($A16,'Rank Calc'!$P$5:$P$53,0)),"")
... A53: 49 | B53: =IFERROR(INDEX('Rank Calc'!$A$5:$A$53,MATCH($A53,'Rank Calc'!$P$5:$P$53,0)),"") | C53: =IFERROR(INDEX('Rank Calc'!$B$5:$B$53,MATCH($A53,'Rank Calc'!$P$5:$P$53,0)),"") | D53: =IFERROR(INDEX('Rank Calc'!$O$5:$O$53,MATCH($A53,'Rank Calc'!$P$5:$P$53,0)),"") | E53: =IFERROR(INDEX('Rank Calc'!$C$5:$C$53,MATCH($A53,'Rank Calc'!$P$5:$P$53,0)),"") | F53: =IFERROR(INDEX('Rank Calc'!$D$5:$D$53,MATCH($A53,'Rank Calc'!$P$5:$P$53,0)),"") | G53: =IFERROR(INDEX('Rank Calc'!$I$5:$I$53,MATCH($A53,'Rank Calc'!$P$5:$P$53,0)),"") | H53: =IFERROR(INDEX('Rank Calc'!$E$5:$E$53,MATCH($A53,'Rank Calc'!$P$5:$P$53,0)),"") | I53: =IFERROR(INDEX('Rank Calc'!$J$5:$J$53,MATCH($A53,'Rank Calc'!$P$5:$P$53,0)),"") | J53: =IFERROR(INDEX('Rank Calc'!$K$5:$K$53,MATCH($A53,'Rank Calc'!$P$5:$P$53,0)),"") | K53: =IFERROR(INDEX('Rank Calc'!$G$5:$G$53,MATCH($A53,'Rank Calc'!$P$5:$P$53,0)),"") | L53: =IFERROR(INDEX('Rank Calc'!$F$5:$F$53,MATCH($A53,'Rank Calc'!$P$5:$P$53,0)),"") | M53: =IFERROR(INDEX('Rank Calc'!$H$5:$H$53,MATCH($A53,'Rank Calc'!$P$5:$P$53,0)),"")

Sheet Holdings
A1: Joint Account (••••5343) - Holdings, Price Targets and Sell Targets
A2: Blue columns are inputs (broker snapshot + routine targets). Green-header columns are formulas. Sell targets are guides for Ryan; the agent never trades the joint account.
A3: Price used: | B3: =Inputs!$B$6 | C3: Close 2026-10-29 | D3: =Inputs!$B$5 | F3: Not priced (check in the app): EPIX^
A5: Symbol | B5: Company | C5: Type | D5: Sector | E5: Shares | F5: Avg Cost | G5: Price | H5: After-hrs | I5: 50-day SMA | J5: 200-day SMA | K5: 60-day Low | L5: 60-day High | M5: 52-wk High | N5: Tgt: Fundamental | O5: Tgt: Robinhood | P5: Tgt: Analysts | Q5: FINAL Price Target | R5: Target Agreement | S5: Valuation | T5: Disruption | U5: Next Earnings | V5: Price Used | W5: Market Value | X5: Cost Basis | Y5: Unrealized P/L $ | Z5: P/L % | AA5: Weight | AB5: After-hrs Move | AC5: vs 50-day | AD5: vs 200-day | AE5: Off 52-wk High | AF5: Upside to Target | AG5: SELL TARGET 1 (trim) | AH5: SELL TARGET 2 (trim) | AI5: Shares per Trim | AJ5: Proceeds at T1 | AK5: DOWNSIDE REVIEW LEVEL | AL5: Cushion to Review | AM5: Trailing Stop (if green) | AN5: Reward : Risk | AO5: ACTION | AP5: RANK | AQ5: Notes
A6: META | B6: Meta Platforms | C6: Stock | D6: Internet | E6: 25.982426 | F6: 631.15 | G6: 624.52 | H6: 618.49 | I6: 668.6 | J6: 632.11 | K6: 537.27 | L6: 779.82 | M6: 779.82 | N6: 890.02 | O6: 850.51 | P6: 840 | Q6: 850.51 | R6: HIGH | S6: FAIR -2% (med) | T6: INNOVATING | U6: n/a | V6: =IF(AND(Inputs!$B$6="After-hours",N(H6)>0),H6,G6) | W6: =E6*V6 | X6: =E6*F6 | Y6: =W6-X6 | Z6: =IFERROR(Y6/X6,"") | AA6: =W6/$W$27 | AB6: =IFERROR(IF(N(H6)>0,H6/G6-1,""),"") | AC6: =IFERROR(V6/I6-1,"") | AD6: =IFERROR(V6/J6-1,"") | AE6: =IFERROR(V6/M6-1,"") | AF6: =IF(N(Q6)>0,Q6/V6-1,"") | AG6: =IF(N(Q6)>0,Q6*Inputs!$B$7,"") | AH6: =IF(N(Q6)>0,Q6*(1+Inputs!$B$8),"") | AI6: =E6*Inputs!$B$9 | AJ6: =IF(N(AG6)>0,AI6*AG6,"") | AK6: =MAX(K6*(1-Inputs!$B$10),F6*(1-IF(ISNUMBER(SEARCH("Lev",C6)),Inputs!$B$12,Inputs!$B$11))) | AL6: =IFERROR(V6/AK6-1,"") | AM6: =IF(V6>=F6/(1-Inputs!$B$13),MAX(F6,L6*(1-Inputs!$B$13)),"not green yet") | AN6: =IF(AND(N(Q6)>0,V6>AK6,AG6>V6),(AG6-V6)/(V6-AK6),"") | AO6: =IF(W6<100,"DUST: clean up",IF(V6<AK6,"REVIEW: below support / max loss",IF(AND(N(Q6)>0,V6>=AH6),"SELL 2nd TRIM, trail the rest",IF(AND(N(Q6)>0,V6>=AG6),"TRIM 1/3 + thesis re-check",IF(AA6>IF(ISNUMBER(SEARCH("Lev",C6)),Inputs!$B$15,Inputs!$B$14),"OVERWEIGHT: trim to cap",IF(IF(ISNUMBER(U6),AND(U6>Inputs!$B$5,U6-Inputs!$B$5<=Inputs!$B$16),FALSE),"HOLD: earnings soon",IF(N(Q6)=0,"HOLD: no target","HOLD"))))))) | AP6: =IFERROR(INDEX('Rank Calc'!$P$5:$P$53,MATCH($A6,'Rank Calc'!$A$5:$A$53,0)),"") | AQ6: Already held (~15% of the joint account).
A7: AMZN | B7: Amazon | C7: Stock | D7: Internet retail / cloud | E7: 61.916672 | F7: 229.2 | G7: 243.79 | H7: 226.96 | I7: 254.89 | J7: 243.44 | K7: 244.3 | L7: 280.14 | M7: 287.2 | N7: 440.05 | O7: 333.68 | P7: 350 | Q7: 350 | R7: MED | S7: DEEP VALUE +100% (low) | T7: INNOVATING | U7: 46324 | V7: =IF(AND(Inputs!$B$6="After-hours",N(H7)>0),H7,G7) | W7: =E7*V7 | X7: =E7*F7 | Y7: =W7-X7 | Z7: =IFERROR(Y7/X7,"") | AA7: =W7/$W$27 | AB7: =IFERROR(IF(N(H7)>0,H7/G7-1,""),"") | AC7: =IFERROR(V7/I7-1,"") | AD7: =IFERROR(V7/J7-1,"") | AE7: =IFERROR(V7/M7-1,"") | AF7: =IF(N(Q7)>0,Q7/V7-1,"") | AG7: =IF(N(Q7)>0,Q7*Inputs!$B$7,"") | AH7: =IF(N(Q7)>0,Q7*(1+Inputs!$B$8),"") | AI7: =E7*Inputs!$B$9 | AJ7: =IF(N(AG7)>0,AI7*AG7,"") | AK7: =MAX(K7*(1-Inputs!$B$10),F7*(1-IF(ISNUMBER(SEARCH("Lev",C7)),Inputs!$B$12,Inputs!$B$11))) | AL7: =IFERROR(V7/AK7-1,"") | AM7: =IF(V7>=F7/(1-Inputs!$B$13),MAX(F7,L7*(1-Inputs!$B$13)),"not green yet") | AN7: =IF(AND(N(Q7)>0,V7>AK7,AG7>V7),(AG7-V7)/(V7-AK7),"") | AO7: =IF(W7<100,"DUST: clean up",IF(V7<AK7,"REVIEW: below support / max loss",IF(AND(N(Q7)>0,V7>=AH7),"SELL 2nd TRIM, trail the rest",IF(AND(N(Q7)>0,V7>=AG7),"TRIM 1/3 + thesis re-check",IF(AA7>IF(ISNUMBER(SEARCH("Lev",C7)),Inputs!$B$15,Inputs!$B$14),"OVERWEIGHT: trim to cap",IF(IF(ISNUMBER(U7),AND(U7>Inputs!$B$5,U7-Inputs!$B$5<=Inputs!$B$16),FALSE),"HOLD: earnings soon",IF(N(Q7)=0,"HOLD: no target","HOLD"))))))) | AP7: =IFERROR(INDEX('Rank Calc'!$P$5:$P$53,MATCH($A7,'Rank Calc'!$A$5:$A$53,0)),"") | AQ7: Q3 EPS 1.89 vs 1.97 est (miss); -6.9% after hours. Below 60-day low AH.
A8: SOXL | B8: Direxion Semis 3x Bull | C8: 3x Lev ETF | D8: Semiconductors | E8: 145 | F8: 86.37 | G8: 102.39 | H8: 87.39 | I8: 122.07 | J8: 124.17 | K8: 80.22 | L8: 169.83 | M8: 302 | Q8: 122.07 | R8: TECH (50-day) | S8: n/a | T8: N/A | U8: n/a | V8: =IF(AND(Inputs!$B$6="After-hours",N(H8)>0),H8,G8) | W8: =E8*V8 | X8: =E8*F8 | Y8: =W8-X8 | Z8: =IFERROR(Y8/X8,"") | AA8: =W8/$W$27 | AB8: =IFERROR(IF(N(H8)>0,H8/G8-1,""),"") | AC8: =IFERROR(V8/I8-1,"") | AD8: =IFERROR(V8/J8-1,"") | AE8: =IFERROR(V8/M8-1,"") | AF8: =IF(N(Q8)>0,Q8/V8-1,"") | AG8: =IF(N(Q8)>0,Q8*Inputs!$B$7,"") | AH8: =IF(N(Q8)>0,Q8*(1+Inputs!$B$8),"") | AI8: =E8*Inputs!$B$9 | AJ8: =IF(N(AG8)>0,AI8*AG8,"") | AK8: =MAX(K8*(1-Inputs!$B$10),F8*(1-IF(ISNUMBER(SEARCH("Lev",C8)),Inputs!$B$12,Inputs!$B$11))) | AL8: =IFERROR(V8/AK8-1,"") | AM8: =IF(V8>=F8/(1-Inputs!$B$13),MAX(F8,L8*(1-Inputs!$B$13)),"not green yet") | AN8: =IF(AND(N(Q8)>0,V8>AK8,AG8>V8),(AG8-V8)/(V8-AK8),"") | AO8: =IF(W8<100,"DUST: clean up",IF(V8<AK8,"REVIEW: below support / max loss",IF(AND(N(Q8)>0,V8>=AH8),"SELL 2nd TRIM, trail the rest",IF(AND(N(Q8)>0,V8>=AG8),"TRIM 1/3 + thesis re-check",IF(AA8>IF(ISNUMBER(SEARCH("Lev",C8)),Inputs!$B$15,Inputs!$B$14),"OVERWEIGHT: trim to cap",IF(IF(ISNUMBER(U8),AND(U8>Inputs!$B$5,U8-Inputs!$B$5<=Inputs!$B$16),FALSE),"HOLD: earnings soon",IF(N(Q8)=0,"HOLD: no target","HOLD"))))))) | AP8: =IFERROR(INDEX('Rank Calc'!$P$5:$P$53,MATCH($A8,'Rank Calc'!$A$5:$A$53,0)),"") | AQ8: 3x daily leverage, decays in chop. No analyst target: target = 50-day SMA (first resistance). -14.6% AH.
A9: SPCX | B9: SpaceX | C9: Stock | D9: Space / telecom / AI | E9: 65 | F9: 154.95 | G9: 143.89 | H9: 140.71 | I9: 149.57 | J9: 147.94 | K9: 105.11 | L9: 176.42 | M9: 225.64 | O9: 256 | P9: 240 | Q9: 248 | R9: MED | S9: n/a | T9: N/A | U9: n/a | V9: =IF(AND(Inputs!$B$6="After-hours",N(H9)>0),H9,G9) | W9: =E9*V9 | X9: =E9*F9 | Y9: =W9-X9 | Z9: =IFERROR(Y9/X9,"") | AA9: =W9/$W$27 | AB9: =IFERROR(IF(N(H9)>0,H9/G9-1,""),"") | AC9: =IFERROR(V9/I9-1,"") | AD9: =IFERROR(V9/J9-1,"") | AE9: =IFERROR(V9/M9-1,"") | AF9: =IF(N(Q9)>0,Q9/V9-1,"") | AG9: =IF(N(Q9)>0,Q9*Inputs!$B$7,"") | AH9: =IF(N(Q9)>0,Q9*(1+Inputs!$B$8),"") | AI9: =E9*Inputs!$B$9 | AJ9: =IF(N(AG9)>0,AI9*AG9,"") | AK9: =MAX(K9*(1-Inputs!$B$10),F9*(1-IF(ISNUMBER(SEARCH("Lev",C9)),Inputs!$B$12,Inputs!$B$11))) | AL9: =IFERROR(V9/AK9-1,"") | AM9: =IF(V9>=F9/(1-Inputs!$B$13),MAX(F9,L9*(1-Inputs!$B$13)),"not green yet") | AN9: =IF(AND(N(Q9)>0,V9>AK9,AG9>V9),(AG9-V9)/(V9-AK9),"") | AO9: =IF(W9<100,"DUST: clean up",IF(V9<AK9,"REVIEW: below support / max loss",IF(AND(N(Q9)>0,V9>=AH9),"SELL 2nd TRIM, trail the rest",IF(AND(N(Q9)>0,V9>=AG9),"TRIM 1/3 + thesis re-check",IF(AA9>IF(ISNUMBER(SEARCH("Lev",C9)),Inputs!$B$15,Inputs!$B$14),"OVERWEIGHT: trim to cap",IF(IF(ISNUMBER(U9),AND(U9>Inputs!$B$5,U9-Inputs!$B$5<=Inputs!$B$16),FALSE),"HOLD: earnings soon",IF(N(Q9)=0,"HOLD: no target","HOLD"))))))) | AP9: =IFERROR(INDEX('Rank Calc'!$P$5:$P$53,MATCH($A9,'Rank Calc'!$A$5:$A$53,0)),"")
A10: NBIS | B10: Nebius Group | C10: Stock | D10: AI cloud | E10: 46 | F10: 162.87 | G10: 171.99 | H10: 164.33 | I10: 211.23 | J10: 177.28 | K10: 149.48 | L10: 280.83 | M10: 299.86 | O10: 286.71 | P10: 250 | Q10: 268.36 | R10: MED | S10: EXPENSIVE -50% (low) | T10: DISRUPTOR | U10: 46336 | V10: =IF(AND(Inputs!$B$6="After-hours",N(H10)>0),H10,G10) | W10: =E10*V10 | X10: =E10*F10 | Y10: =W10-X10 | Z10: =IFERROR(Y10/X10,"") | AA10: =W10/$W$27 | AB10: =IFERROR(IF(N(H10)>0,H10/G10-1,""),"") | AC10: =IFERROR(V10/I10-1,"") | AD10: =IFERROR(V10/J10-1,"") | AE10: =IFERROR(V10/M10-1,"") | AF10: =IF(N(Q10)>0,Q10/V10-1,"") | AG10: =IF(N(Q10)>0,Q10*Inputs!$B$7,"") | AH10: =IF(N(Q10)>0,Q10*(1+Inputs!$B$8),"") | AI10: =E10*Inputs!$B$9 | AJ10: =IF(N(AG10)>0,AI10*AG10,"") | AK10: =MAX(K10*(1-Inputs!$B$10),F10*(1-IF(ISNUMBER(SEARCH("Lev",C10)),Inputs!$B$12,Inputs!$B$11))) | AL10: =IFERROR(V10/AK10-1,"") | AM10: =IF(V10>=F10/(1-Inputs!$B$13),MAX(F10,L10*(1-Inputs!$B$13)),"not green yet") | AN10: =IF(AND(N(Q10)>0,V10>AK10,AG10>V10),(AG10-V10)/(V10-AK10),"") | AO10: =IF(W10<100,"DUST: clean up",IF(V10<AK10,"REVIEW: below support / max loss",IF(AND(N(Q10)>0,V10>=AH10),"SELL 2nd TRIM, trail the rest",IF(AND(N(Q10)>0,V10>=AG10),"TRIM 1/3 + thesis re-check",IF(AA10>IF(ISNUMBER(SEARCH("Lev",C10)),Inputs!$B$15,Inputs!$B$14),"OVERWEIGHT: trim to cap",IF(IF(ISNUMBER(U10),AND(U10>Inputs!$B$5,U10-Inputs!$B$5<=Inputs!$B$16),FALSE),"HOLD: earnings soon",IF(N(Q10)=0,"HOLD: no target","HOLD"))))))) | AP10: =IFERROR(INDEX('Rank Calc'!$P$5:$P$53,MATCH($A10,'Rank Calc'!$A$5:$A$53,0)),"") | AQ10: Earnings date unverified.
A11: MPWR | B11: Monolithic Power | C11: Stock | D11: Semiconductors | E11: 6 | F11: 1165.4 | G11: 1198.81 | H11: 1190.01 | I11: 1276.92 | J11: 1315.16 | K11: 1126.57 | L11: 1491.64 | M11: 1714.09 | N11: 1870.2 | O11: 1807.46 | Q11: 1838.83 | R11: HIGH | S11: RICH -23% (low) | T11: INNOVATING | U11: 46324 | V11: =IF(AND(Inputs!$B$6="After-hours",N(H11)>0),H11,G11) | W11: =E11*V11 | X11: =E11*F11 | Y11: =W11-X11 | Z11: =IFERROR(Y11/X11,"") | AA11: =W11/$W$27 | AB11: =IFERROR(IF(N(H11)>0,H11/G11-1,""),"") | AC11: =IFERROR(V11/I11-1,"") | AD11: =IFERROR(V11/J11-1,"") | AE11: =IFERROR(V11/M11-1,"") | AF11: =IF(N(Q11)>0,Q11/V11-1,"") | AG11: =IF(N(Q11)>0,Q11*Inputs!$B$7,"") | AH11: =IF(N(Q11)>0,Q11*(1+Inputs!$B$8),"") | AI11: =E11*Inputs!$B$9 | AJ11: =IF(N(AG11)>0,AI11*AG11,"") | AK11: =MAX(K11*(1-Inputs!$B$10),F11*(1-IF(ISNUMBER(SEARCH("Lev",C11)),Inputs!$B$12,Inputs!$B$11))) | AL11: =IFERROR(V11/AK11-1,"") | AM11: =IF(V11>=F11/(1-Inputs!$B$13),MAX(F11,L11*(1-Inputs!$B$13)),"not green yet") | AN11: =IF(AND(N(Q11)>0,V11>AK11,AG11>V11),(AG11-V11)/(V11-AK11),"") | AO11: =IF(W11<100,"DUST: clean up",IF(V11<AK11,"REVIEW: below support / max loss",IF(AND(N(Q11)>0,V11>=AH11),"SELL 2nd TRIM, trail the rest",IF(AND(N(Q11)>0,V11>=AG11),"TRIM 1/3 + thesis re-check",IF(AA11>IF(ISNUMBER(SEARCH("Lev",C11)),Inputs!$B$15,Inputs!$B$14),"OVERWEIGHT: trim to cap",IF(IF(ISNUMBER(U11),AND(U11>Inputs!$B$5,U11-Inputs!$B$5<=Inputs!$B$16),FALSE),"HOLD: earnings soon",IF(N(Q11)=0,"HOLD: no target","HOLD"))))))) | AP11: =IFERROR(INDEX('Rank Calc'!$P$5:$P$53,MATCH($A11,'Rank Calc'!$A$5:$A$53,0)),"") | AQ11: Q3 EPS 8.19 vs 7.56 est (beat).
A12: CDNS | B12: Cadence Design | C12: Stock | D12: EDA software | E12: 20 | F12: 316.43 | G12: 342.75 | H12: 337.94 | I12: 320.24 | J12: 327.46 | K12: 273.07 | L12: 361.91 | M12: 416.69 | N12: 593.26 | O12: 415.04 | Q12: 504.15 | R12: LOW | S12: FAIR -9% (high) | T12: INNOVATING | U12: n/a | V12: =IF(AND(Inputs!$B$6="After-hours",N(H12)>0),H12,G12) | W12: =E12*V12 | X12: =E12*F12 | Y12: =W12-X12 | Z12: =IFERROR(Y12/X12,"") | AA12: =W12/$W$27 | AB12: =IFERROR(IF(N(H12)>0,H12/G12-1,""),"") | AC12: =IFERROR(V12/I12-1,"") | AD12: =IFERROR(V12/J12-1,"") | AE12: =IFERROR(V12/M12-1,"") | AF12: =IF(N(Q12)>0,Q12/V12-1,"") | AG12: =IF(N(Q12)>0,Q12*Inputs!$B$7,"") | AH12: =IF(N(Q12)>0,Q12*(1+Inputs!$B$8),"") | AI12: =E12*Inputs!$B$9 | AJ12: =IF(N(AG12)>0,AI12*AG12,"") | AK12: =MAX(K12*(1-Inputs!$B$10),F12*(1-IF(ISNUMBER(SEARCH("Lev",C12)),Inputs!$B$12,Inputs!$B$11))) | AL12: =IFERROR(V12/AK12-1,"") | AM12: =IF(V12>=F12/(1-Inputs!$B$13),MAX(F12,L12*(1-Inputs!$B$13)),"not green yet") | AN12: =IF(AND(N(Q12)>0,V12>AK12,AG12>V12),(AG12-V12)/(V12-AK12),"") | AO12: =IF(W12<100,"DUST: clean up",IF(V12<AK12,"REVIEW: below support / max loss",IF(AND(N(Q12)>0,V12>=AH12),"SELL 2nd TRIM, trail the rest",IF(AND(N(Q12)>0,V12>=AG12),"TRIM 1/3 + thesis re-check",IF(AA12>IF(ISNUMBER(SEARCH("Lev",C12)),Inputs!$B$15,Inputs!$B$14),"OVERWEIGHT: trim to cap",IF(IF(ISNUMBER(U12),AND(U12>Inputs!$B$5,U12-Inputs!$B$5<=Inputs!$B$16),FALSE),"HOLD: earnings soon",IF(N(Q12)=0,"HOLD: no target","HOLD"))))))) | AP12: =IFERROR(INDEX('Rank Calc'!$P$5:$P$53,MATCH($A12,'Rank Calc'!$A$5:$A$53,0)),"") | AQ12: Target agreement LOW: fundamental and Robinhood targets 35% apart.
A13: NOW | B13: ServiceNow | C13: Stock | D13: Software | E13: 46.881838 | F13: 103.9 | G13: 109.67 | H13: 109.23 | I13: 139.99 | J13: 115.34 | K13: 111.8 | L13: 159.5 | M13: 192.97 | O13: 158.78 | P13: 195.5 | Q13: 177.14 | R13: MED | S13: DEEP VALUE +92% (low) | T13: DISRUPTOR | U13: n/a | V13: =IF(AND(Inputs!$B$6="After-hours",N(H13)>0),H13,G13) | W13: =E13*V13 | X13: =E13*F13 | Y13: =W13-X13 | Z13: =IFERROR(Y13/X13,"") | AA13: =W13/$W$27 | AB13: =IFERROR(IF(N(H13)>0,H13/G13-1,""),"") | AC13: =IFERROR(V13/I13-1,"") | AD13: =IFERROR(V13/J13-1,"") | AE13: =IFERROR(V13/M13-1,"") | AF13: =IF(N(Q13)>0,Q13/V13-1,"") | AG13: =IF(N(Q13)>0,Q13*Inputs!$B$7,"") | AH13: =IF(N(Q13)>0,Q13*(1+Inputs!$B$8),"") | AI13: =E13*Inputs!$B$9 | AJ13: =IF(N(AG13)>0,AI13*AG13,"") | AK13: =MAX(K13*(1-Inputs!$B$10),F13*(1-IF(ISNUMBER(SEARCH("Lev",C13)),Inputs!$B$12,Inputs!$B$11))) | AL13: =IFERROR(V13/AK13-1,"") | AM13: =IF(V13>=F13/(1-Inputs!$B$13),MAX(F13,L13*(1-Inputs!$B$13)),"not green yet") | AN13: =IF(AND(N(Q13)>0,V13>AK13,AG13>V13),(AG13-V13)/(V13-AK13),"") | AO13: =IF(W13<100,"DUST: clean up",IF(V13<AK13,"REVIEW: below support / max loss",IF(AND(N(Q13)>0,V13>=AH13),"SELL 2nd TRIM, trail the rest",IF(AND(N(Q13)>0,V13>=AG13),"TRIM 1/3 + thesis re-check",IF(AA13>IF(ISNUMBER(SEARCH("Lev",C13)),Inputs!$B$15,Inputs!$B$14),"OVERWEIGHT: trim to cap",IF(IF(ISNUMBER(U13),AND(U13>Inputs!$B$5,U13-Inputs!$B$5<=Inputs!$B$16),FALSE),"HOLD: earnings soon",IF(N(Q13)=0,"HOLD: no target","HOLD"))))))) | AP13: =IFERROR(INDEX('Rank Calc'!$P$5:$P$53,MATCH($A13,'Rank Calc'!$A$5:$A$53,0)),"") | AQ13: Closed below its 60-day low on 10/29.
A14: ASND | B14: Ascendis Pharma | C14: Stock | D14: Biotech | E14: 20 | F14: 226.14 | G14: 253 | H14: 253 | I14: 242.38 | J14: 237.93 | K14: 219.52 | L14: 272.47 | M14: 282.15 | O14: 302.81 | P14: 302 | Q14: 302.4 | R14: MED | S14: n/a | T14: DISRUPTOR | U14: 46337 | V14: =IF(AND(Inputs!$B$6="After-hours",N(H14)>0),H14,G14) | W14: =E14*V14 | X14: =E14*F14 | Y14: =W14-X14 | Z14: =IFERROR(Y14/X14,"") | AA14: =W14/$W$27 | AB14: =IFERROR(IF(N(H14)>0,H14/G14-1,""),"") | AC14: =IFERROR(V14/I14-1,"") | AD14: =IFERROR(V14/J14-1,"") | AE14: =IFERROR(V14/M14-1,"") | AF14: =IF(N(Q14)>0,Q14/V14-1,"") | AG14: =IF(N(Q14)>0,Q14*Inputs!$B$7,"") | AH14: =IF(N(Q14)>0,Q14*(1+Inputs!$B$8),"") | AI14: =E14*Inputs!$B$9 | AJ14: =IF(N(AG14)>0,AI14*AG14,"") | AK14: =MAX(K14*(1-Inputs!$B$10),F14*(1-IF(ISNUMBER(SEARCH("Lev",C14)),Inputs!$B$12,Inputs!$B$11))) | AL14: =IFERROR(V14/AK14-1,"") | AM14: =IF(V14>=F14/(1-Inputs!$B$13),MAX(F14,L14*(1-Inputs!$B$13)),"not green yet") | AN14: =IF(AND(N(Q14)>0,V14>AK14,AG14>V14),(AG14-V14)/(V14-AK14),"") | AO14: =IF(W14<100,"DUST: clean up",IF(V14<AK14,"REVIEW: below support / max loss",IF(AND(N(Q14)>0,V14>=AH14),"SELL 2nd TRIM, trail the rest",IF(AND(N(Q14)>0,V14>=AG14),"TRIM 1/3 + thesis re-check",IF(AA14>IF(ISNUMBER(SEARCH("Lev",C14)),Inputs!$B$15,Inputs!$B$14),"OVERWEIGHT: trim to cap",IF(IF(ISNUMBER(U14),AND(U14>Inputs!$B$5,U14-Inputs!$B$5<=Inputs!$B$16),FALSE),"HOLD: earnings soon",IF(N(Q14)=0,"HOLD: no target","HOLD"))))))) | AP14: =IFERROR(INDEX('Rank Calc'!$P$5:$P$53,MATCH($A14,'Rank Calc'!$A$5:$A$53,0)),"") | AQ14: Earnings date unverified.
A15: VST | B15: Vistra | C15: Stock | D15: Power generation | E15: 35 | F15: 140.54 | G15: 140.95 | H15: 137.85 | I15: 145.12 | J15: 153.77 | K15: 133.44 | L15: 168.75 | M15: 198.82 | N15: 234.71 | O15: 207.86 | P15: 224 | Q15: 224 | R15: HIGH | S15: EXPENSIVE -35% (low) | T15: STABLE | U15: 46332 | V15: =IF(AND(Inputs!$B$6="After-hours",N(H15)>0),H15,G15) | W15: =E15*V15 | X15: =E15*F15 | Y15: =W15-X15 | Z15: =IFERROR(Y15/X15,"") | AA15: =W15/$W$27 | AB15: =IFERROR(IF(N(H15)>0,H15/G15-1,""),"") | AC15: =IFERROR(V15/I15-1,"") | AD15: =IFERROR(V15/J15-1,"") | AE15: =IFERROR(V15/M15-1,"") | AF15: =IF(N(Q15)>0,Q15/V15-1,"") | AG15: =IF(N(Q15)>0,Q15*Inputs!$B$7,"") | AH15: =IF(N(Q15)>0,Q15*(1+Inputs!$B$8),"") | AI15: =E15*Inputs!$B$9 | AJ15: =IF(N(AG15)>0,AI15*AG15,"") | AK15: =MAX(K15*(1-Inputs!$B$10),F15*(1-IF(ISNUMBER(SEARCH("Lev",C15)),Inputs!$B$12,Inputs!$B$11))) | AL15: =IFERROR(V15/AK15-1,"") | AM15: =IF(V15>=F15/(1-Inputs!$B$13),MAX(F15,L15*(1-Inputs!$B$13)),"not green yet") | AN15: =IF(AND(N(Q15)>0,V15>AK15,AG15>V15),(AG15-V15)/(V15-AK15),"") | AO15: =IF(W15<100,"DUST: clean up",IF(V15<AK15,"REVIEW: below support / max loss",IF(AND(N(Q15)>0,V15>=AH15),"SELL 2nd TRIM, trail the rest",IF(AND(N(Q15)>0,V15>=AG15),"TRIM 1/3 + thesis re-check",IF(AA15>IF(ISNUMBER(SEARCH("Lev",C15)),Inputs!$B$15,Inputs!$B$14),"OVERWEIGHT: trim to cap",IF(IF(ISNUMBER(U15),AND(U15>Inputs!$B$5,U15-Inputs!$B$5<=Inputs!$B$16),FALSE),"HOLD: earnings soon",IF(N(Q15)=0,"HOLD: no target","HOLD"))))))) | AP15: =IFERROR(INDEX('Rank Calc'!$P$5:$P$53,MATCH($A15,'Rank Calc'!$A$5:$A$53,0)),"")
A16: CRDO | B16: Credo Technology | C16: Stock | D16: Semiconductors | E16: 25 | F16: 164.53 | G16: 165.29 | H16: 155.65 | I16: 190.17 | J16: 181.14 | K16: 142.89 | L16: 286.24 | M16: 308.67 | N16: 189.97 | O16: 281.59 | P16: 292 | Q16: 281.59 | R16: LOW | S16: EXPENSIVE -31% (low) | T16: DISRUPTOR | U16: n/a | V16: =IF(AND(Inputs!$B$6="After-hours",N(H16)>0),H16,G16) | W16: =E16*V16 | X16: =E16*F16 | Y16: =W16-X16 | Z16: =IFERROR(Y16/X16,"") | AA16: =W16/$W$27 | AB16: =IFERROR(IF(N(H16)>0,H16/G16-1,""),"") | AC16: =IFERROR(V16/I16-1,"") | AD16: =IFERROR(V16/J16-1,"") | AE16: =IFERROR(V16/M16-1,"") | AF16: =IF(N(Q16)>0,Q16/V16-1,"") | AG16: =IF(N(Q16)>0,Q16*Inputs!$B$7,"") | AH16: =IF(N(Q16)>0,Q16*(1+Inputs!$B$8),"") | AI16: =E16*Inputs!$B$9 | AJ16: =IF(N(AG16)>0,AI16*AG16,"") | AK16: =MAX(K16*(1-Inputs!$B$10),F16*(1-IF(ISNUMBER(SEARCH("Lev",C16)),Inputs!$B$12,Inputs!$B$11))) | AL16: =IFERROR(V16/AK16-1,"") | AM16: =IF(V16>=F16/(1-Inputs!$B$13),MAX(F16,L16*(1-Inputs!$B$13)),"not green yet") | AN16: =IF(AND(N(Q16)>0,V16>AK16,AG16>V16),(AG16-V16)/(V16-AK16),"") | AO16: =IF(W16<100,"DUST: clean up",IF(V16<AK16,"REVIEW: below support / max loss",IF(AND(N(Q16)>0,V16>=AH16),"SELL 2nd TRIM, trail the rest",IF(AND(N(Q16)>0,V16>=AG16),"TRIM 1/3 + thesis re-check",IF(AA16>IF(ISNUMBER(SEARCH("Lev",C16)),Inputs!$B$15,Inputs!$B$14),"OVERWEIGHT: trim to cap",IF(IF(ISNUMBER(U16),AND(U16>Inputs!$B$5,U16-Inputs!$B$5<=Inputs!$B$16),FALSE),"HOLD: earnings soon",IF(N(Q16)=0,"HOLD: no target","HOLD"))))))) | AP16: =IFERROR(INDEX('Rank Calc'!$P$5:$P$53,MATCH($A16,'Rank Calc'!$A$5:$A$53,0)),"") | AQ16: -5.8% after hours.
A17: SNDK | B17: Sandisk | C17: Stock | D17: Memory | E17: 3 | F17: 1278.16 | G17: 1330.05 | H17: 1309.34 | I17: 1568.4 | J17: 1255.73 | K17: 1163.09 | L17: 1909.48 | M17: 2354.39 | O17: 2287.38 | P17: 1737.5 | Q17: 2012.44 | R17: MED | S17: EXPENSIVE -50% (low) | T17: INNOVATING | U17: 46324 | V17: =IF(AND(Inputs!$B$6="After-hours",N(H17)>0),H17,G17) | W17: =E17*V17 | X17: =E17*F17 | Y17: =W17-X17 | Z17: =IFERROR(Y17/X17,"") | AA17: =W17/$W$27 | AB17: =IFERROR(IF(N(H17)>0,H17/G17-1,""),"") | AC17: =IFERROR(V17/I17-1,"") | AD17: =IFERROR(V17/J17-1,"") | AE17: =IFERROR(V17/M17-1,"") | AF17: =IF(N(Q17)>0,Q17/V17-1,"") | AG17: =IF(N(Q17)>0,Q17*Inputs!$B$7,"") | AH17: =IF(N(Q17)>0,Q17*(1+Inputs!$B$8),"") | AI17: =E17*Inputs!$B$9 | AJ17: =IF(N(AG17)>0,AI17*AG17,"") | AK17: =MAX(K17*(1-Inputs!$B$10),F17*(1-IF(ISNUMBER(SEARCH("Lev",C17)),Inputs!$B$12,Inputs!$B$11))) | AL17: =IFERROR(V17/AK17-1,"") | AM17: =IF(V17>=F17/(1-Inputs!$B$13),MAX(F17,L17*(1-Inputs!$B$13)),"not green yet") | AN17: =IF(AND(N(Q17)>0,V17>AK17,AG17>V17),(AG17-V17)/(V17-AK17),"") | AO17: =IF(W17<100,"DUST: clean up",IF(V17<AK17,"REVIEW: below support / max loss",IF(AND(N(Q17)>0,V17>=AH17),"SELL 2nd TRIM, trail the rest",IF(AND(N(Q17)>0,V17>=AG17),"TRIM 1/3 + thesis re-check",IF(AA17>IF(ISNUMBER(SEARCH("Lev",C17)),Inputs!$B$15,Inputs!$B$14),"OVERWEIGHT: trim to cap",IF(IF(ISNUMBER(U17),AND(U17>Inputs!$B$5,U17-Inputs!$B$5<=Inputs!$B$16),FALSE),"HOLD: earnings soon",IF(N(Q17)=0,"HOLD: no target","HOLD"))))))) | AP17: =IFERROR(INDEX('Rank Calc'!$P$5:$P$53,MATCH($A17,'Rank Calc'!$A$5:$A$53,0)),"") | AQ17: FQ1 EPS 49.51 vs 46.36 est (beat).
A18: OKLO | B18: Oklo | C18: Stock | D18: Nuclear (pre-revenue) | E18: 100 | F18: 26.73 | G18: 26.81 | H18: 25.78 | I18: 35.86 | J18: 54.21 | K18: 25.39 | L18: 49.48 | M18: 145.3 | O18: 62.83 | P18: 37 | Q18: 49.91 | R18: LOW | S18: n/a | T18: N/A | U18: 46332 | V18: =IF(AND(Inputs!$B$6="After-hours",N(H18)>0),H18,G18) | W18: =E18*V18 | X18: =E18*F18 | Y18: =W18-X18 | Z18: =IFERROR(Y18/X18,"") | AA18: =W18/$W$27 | AB18: =IFERROR(IF(N(H18)>0,H18/G18-1,""),"") | AC18: =IFERROR(V18/I18-1,"") | AD18: =IFERROR(V18/J18-1,"") | AE18: =IFERROR(V18/M18-1,"") | AF18: =IF(N(Q18)>0,Q18/V18-1,"") | AG18: =IF(N(Q18)>0,Q18*Inputs!$B$7,"") | AH18: =IF(N(Q18)>0,Q18*(1+Inputs!$B$8),"") | AI18: =E18*Inputs!$B$9 | AJ18: =IF(N(AG18)>0,AI18*AG18,"") | AK18: =MAX(K18*(1-Inputs!$B$10),F18*(1-IF(ISNUMBER(SEARCH("Lev",C18)),Inputs!$B$12,Inputs!$B$11))) | AL18: =IFERROR(V18/AK18-1,"") | AM18: =IF(V18>=F18/(1-Inputs!$B$13),MAX(F18,L18*(1-Inputs!$B$13)),"not green yet") | AN18: =IF(AND(N(Q18)>0,V18>AK18,AG18>V18),(AG18-V18)/(V18-AK18),"") | AO18: =IF(W18<100,"DUST: clean up",IF(V18<AK18,"REVIEW: below support / max loss",IF(AND(N(Q18)>0,V18>=AH18),"SELL 2nd TRIM, trail the rest",IF(AND(N(Q18)>0,V18>=AG18),"TRIM 1/3 + thesis re-check",IF(AA18>IF(ISNUMBER(SEARCH("Lev",C18)),Inputs!$B$15,Inputs!$B$14),"OVERWEIGHT: trim to cap",IF(IF(ISNUMBER(U18),AND(U18>Inputs!$B$5,U18-Inputs!$B$5<=Inputs!$B$16),FALSE),"HOLD: earnings soon",IF(N(Q18)=0,"HOLD: no target","HOLD"))))))) | AP18: =IFERROR(INDEX('Rank Calc'!$P$5:$P$53,MATCH($A18,'Rank Calc'!$A$5:$A$53,0)),"") | AQ18: At 52-week low. Targets disagree (52% spread).
A19: AAOX | B19: AAOI 2x Leveraged ETF | C19: 2x Lev ETF | D19: Optical networking | E19: 500 | F19: 3.84 | G19: 5.1 | H19: 4.49 | I19: 9.57 | J19: 28.89 | K19: 3.6 | L19: 27.57 | M19: 103 | Q19: 9.57 | R19: TECH (50-day) | S19: n/a | T19: N/A | U19: n/a | V19: =IF(AND(Inputs!$B$6="After-hours",N(H19)>0),H19,G19) | W19: =E19*V19 | X19: =E19*F19 | Y19: =W19-X19 | Z19: =IFERROR(Y19/X19,"") | AA19: =W19/$W$27 | AB19: =IFERROR(IF(N(H19)>0,H19/G19-1,""),"") | AC19: =IFERROR(V19/I19-1,"") | AD19: =IFERROR(V19/J19-1,"") | AE19: =IFERROR(V19/M19-1,"") | AF19: =IF(N(Q19)>0,Q19/V19-1,"") | AG19: =IF(N(Q19)>0,Q19*Inputs!$B$7,"") | AH19: =IF(N(Q19)>0,Q19*(1+Inputs!$B$8),"") | AI19: =E19*Inputs!$B$9 | AJ19: =IF(N(AG19)>0,AI19*AG19,"") | AK19: =MAX(K19*(1-Inputs!$B$10),F19*(1-IF(ISNUMBER(SEARCH("Lev",C19)),Inputs!$B$12,Inputs!$B$11))) | AL19: =IFERROR(V19/AK19-1,"") | AM19: =IF(V19>=F19/(1-Inputs!$B$13),MAX(F19,L19*(1-Inputs!$B$13)),"not green yet") | AN19: =IF(AND(N(Q19)>0,V19>AK19,AG19>V19),(AG19-V19)/(V19-AK19),"") | AO19: =IF(W19<100,"DUST: clean up",IF(V19<AK19,"REVIEW: below support / max loss",IF(AND(N(Q19)>0,V19>=AH19),"SELL 2nd TRIM, trail the rest",IF(AND(N(Q19)>0,V19>=AG19),"TRIM 1/3 + thesis re-check",IF(AA19>IF(ISNUMBER(SEARCH("Lev",C19)),Inputs!$B$15,Inputs!$B$14),"OVERWEIGHT: trim to cap",IF(IF(ISNUMBER(U19),AND(U19>Inputs!$B$5,U19-Inputs!$B$5<=Inputs!$B$16),FALSE),"HOLD: earnings soon",IF(N(Q19)=0,"HOLD: no target","HOLD"))))))) | AP19: =IFERROR(INDEX('Rank Calc'!$P$5:$P$53,MATCH($A19,'Rank Calc'!$A$5:$A$53,0)),"") | AQ19: 2x daily leverage on one stock; -95% from 52-wk high. Target = 50-day SMA.
A20: GOOGL | B20: Alphabet | C20: Stock | D20: Internet | E20: 6.848872 | F20: 297.58 | G20: 283.82 | H20: 282.23 | I20: 341.11 | J20: 341.14 | K20: 316.6 | L20: 364.17 | M20: 408.61 | N20: 367.54 | O20: 405.31 | P20: 425 | Q20: 405.31 | R20: HIGH | S20: RICH -12% (low) | T20: DISRUPTOR | U20: n/a | V20: =IF(AND(Inputs!$B$6="After-hours",N(H20)>0),H20,G20) | W20: =E20*V20 | X20: =E20*F20 | Y20: =W20-X20 | Z20: =IFERROR(Y20/X20,"") | AA20: =W20/$W$27 | AB20: =IFERROR(IF(N(H20)>0,H20/G20-1,""),"") | AC20: =IFERROR(V20/I20-1,"") | AD20: =IFERROR(V20/J20-1,"") | AE20: =IFERROR(V20/M20-1,"") | AF20: =IF(N(Q20)>0,Q20/V20-1,"") | AG20: =IF(N(Q20)>0,Q20*Inputs!$B$7,"") | AH20: =IF(N(Q20)>0,Q20*(1+Inputs!$B$8),"") | AI20: =E20*Inputs!$B$9 | AJ20: =IF(N(AG20)>0,AI20*AG20,"") | AK20: =MAX(K20*(1-Inputs!$B$10),F20*(1-IF(ISNUMBER(SEARCH("Lev",C20)),Inputs!$B$12,Inputs!$B$11))) | AL20: =IFERROR(V20/AK20-1,"") | AM20: =IF(V20>=F20/(1-Inputs!$B$13),MAX(F20,L20*(1-Inputs!$B$13)),"not green yet") | AN20: =IF(AND(N(Q20)>0,V20>AK20,AG20>V20),(AG20-V20)/(V20-AK20),"") | AO20: =IF(W20<100,"DUST: clean up",IF(V20<AK20,"REVIEW: below support / max loss",IF(AND(N(Q20)>0,V20>=AH20),"SELL 2nd TRIM, trail the rest",IF(AND(N(Q20)>0,V20>=AG20),"TRIM 1/3 + thesis re-check",IF(AA20>IF(ISNUMBER(SEARCH("Lev",C20)),Inputs!$B$15,Inputs!$B$14),"OVERWEIGHT: trim to cap",IF(IF(ISNUMBER(U20),AND(U20>Inputs!$B$5,U20-Inputs!$B$5<=Inputs!$B$16),FALSE),"HOLD: earnings soon",IF(N(Q20)=0,"HOLD: no target","HOLD"))))))) | AP20: =IFERROR(INDEX('Rank Calc'!$P$5:$P$53,MATCH($A20,'Rank Calc'!$A$5:$A$53,0)),"") | AQ20: Well below 60-day low and both moving averages.
A21: IONQ | B21: IonQ | C21: Stock | D21: Quantum computing | E21: 30 | F21: 33.21 | G21: 31.72 | H21: 30.81 | I21: 38.44 | J21: 42.15 | K21: 29.94 | L21: 47.95 | M21: 73.65 | O21: 65.77 | Q21: 65.77 | R21: LOW | S21: n/a | T21: AT RISK | U21: 46331 | V21: =IF(AND(Inputs!$B$6="After-hours",N(H21)>0),H21,G21) | W21: =E21*V21 | X21: =E21*F21 | Y21: =W21-X21 | Z21: =IFERROR(Y21/X21,"") | AA21: =W21/$W$27 | AB21: =IFERROR(IF(N(H21)>0,H21/G21-1,""),"") | AC21: =IFERROR(V21/I21-1,"") | AD21: =IFERROR(V21/J21-1,"") | AE21: =IFERROR(V21/M21-1,"") | AF21: =IF(N(Q21)>0,Q21/V21-1,"") | AG21: =IF(N(Q21)>0,Q21*Inputs!$B$7,"") | AH21: =IF(N(Q21)>0,Q21*(1+Inputs!$B$8),"") | AI21: =E21*Inputs!$B$9 | AJ21: =IF(N(AG21)>0,AI21*AG21,"") | AK21: =MAX(K21*(1-Inputs!$B$10),F21*(1-IF(ISNUMBER(SEARCH("Lev",C21)),Inputs!$B$12,Inputs!$B$11))) | AL21: =IFERROR(V21/AK21-1,"") | AM21: =IF(V21>=F21/(1-Inputs!$B$13),MAX(F21,L21*(1-Inputs!$B$13)),"not green yet") | AN21: =IF(AND(N(Q21)>0,V21>AK21,AG21>V21),(AG21-V21)/(V21-AK21),"") | AO21: =IF(W21<100,"DUST: clean up",IF(V21<AK21,"REVIEW: below support / max loss",IF(AND(N(Q21)>0,V21>=AH21),"SELL 2nd TRIM, trail the rest",IF(AND(N(Q21)>0,V21>=AG21),"TRIM 1/3 + thesis re-check",IF(AA21>IF(ISNUMBER(SEARCH("Lev",C21)),Inputs!$B$15,Inputs!$B$14),"OVERWEIGHT: trim to cap",IF(IF(ISNUMBER(U21),AND(U21>Inputs!$B$5,U21-Inputs!$B$5<=Inputs!$B$16),FALSE),"HOLD: earnings soon",IF(N(Q21)=0,"HOLD: no target","HOLD"))))))) | AP21: =IFERROR(INDEX('Rank Calc'!$P$5:$P$53,MATCH($A21,'Rank Calc'!$A$5:$A$53,0)),"") | AQ21: Only one target method available.
A22: AUR | B22: Aurora Innovation | C22: Stock | D22: Autonomous trucking | E22: 200 | F22: 4.91 | G22: 4.405 | H22: 4.37 | I22: 5.73 | J22: 5.63 | K22: 4.4 | L22: 7.16 | M22: 8.57 | O22: 11.33 | P22: 12.5 | Q22: 11.91 | R22: MED | S22: n/a | T22: INNOVATING | U22: n/a | V22: =IF(AND(Inputs!$B$6="After-hours",N(H22)>0),H22,G22) | W22: =E22*V22 | X22: =E22*F22 | Y22: =W22-X22 | Z22: =IFERROR(Y22/X22,"") | AA22: =W22/$W$27 | AB22: =IFERROR(IF(N(H22)>0,H22/G22-1,""),"") | AC22: =IFERROR(V22/I22-1,"") | AD22: =IFERROR(V22/J22-1,"") | AE22: =IFERROR(V22/M22-1,"") | AF22: =IF(N(Q22)>0,Q22/V22-1,"") | AG22: =IF(N(Q22)>0,Q22*Inputs!$B$7,"") | AH22: =IF(N(Q22)>0,Q22*(1+Inputs!$B$8),"") | AI22: =E22*Inputs!$B$9 | AJ22: =IF(N(AG22)>0,AI22*AG22,"") | AK22: =MAX(K22*(1-Inputs!$B$10),F22*(1-IF(ISNUMBER(SEARCH("Lev",C22)),Inputs!$B$12,Inputs!$B$11))) | AL22: =IFERROR(V22/AK22-1,"") | AM22: =IF(V22>=F22/(1-Inputs!$B$13),MAX(F22,L22*(1-Inputs!$B$13)),"not green yet") | AN22: =IF(AND(N(Q22)>0,V22>AK22,AG22>V22),(AG22-V22)/(V22-AK22),"") | AO22: =IF(W22<100,"DUST: clean up",IF(V22<AK22,"REVIEW: below support / max loss",IF(AND(N(Q22)>0,V22>=AH22),"SELL 2nd TRIM, trail the rest",IF(AND(N(Q22)>0,V22>=AG22),"TRIM 1/3 + thesis re-check",IF(AA22>IF(ISNUMBER(SEARCH("Lev",C22)),Inputs!$B$15,Inputs!$B$14),"OVERWEIGHT: trim to cap",IF(IF(ISNUMBER(U22),AND(U22>Inputs!$B$5,U22-Inputs!$B$5<=Inputs!$B$16),FALSE),"HOLD: earnings soon",IF(N(Q22)=0,"HOLD: no target","HOLD"))))))) | AP22: =IFERROR(INDEX('Rank Calc'!$P$5:$P$53,MATCH($A22,'Rank Calc'!$A$5:$A$53,0)),"") | AQ22: Sitting on its 60-day low.
A23: QQQI | B23: NEOS Nasdaq-100 Income | C23: ETF | D23: Nasdaq-100 covered call | E23: 0.567476 | F23: 53.83 | G23: 53.42 | H23: 52.61 | I23: 54.72 | J23: 54.18 | K23: 52.36 | L23: 56.84 | M23: 57.84 | R23: n/a | S23: n/a | T23: N/A | U23: n/a | V23: =IF(AND(Inputs!$B$6="After-hours",N(H23)>0),H23,G23) | W23: =E23*V23 | X23: =E23*F23 | Y23: =W23-X23 | Z23: =IFERROR(Y23/X23,"") | AA23: =W23/$W$27 | AB23: =IFERROR(IF(N(H23)>0,H23/G23-1,""),"") | AC23: =IFERROR(V23/I23-1,"") | AD23: =IFERROR(V23/J23-1,"") | AE23: =IFERROR(V23/M23-1,"") | AF23: =IF(N(Q23)>0,Q23/V23-1,"") | AG23: =IF(N(Q23)>0,Q23*Inputs!$B$7,"") | AH23: =IF(N(Q23)>0,Q23*(1+Inputs!$B$8),"") | AI23: =E23*Inputs!$B$9 | AJ23: =IF(N(AG23)>0,AI23*AG23,"") | AK23: =MAX(K23*(1-Inputs!$B$10),F23*(1-IF(ISNUMBER(SEARCH("Lev",C23)),Inputs!$B$12,Inputs!$B$11))) | AL23: =IFERROR(V23/AK23-1,"") | AM23: =IF(V23>=F23/(1-Inputs!$B$13),MAX(F23,L23*(1-Inputs!$B$13)),"not green yet") | AN23: =IF(AND(N(Q23)>0,V23>AK23,AG23>V23),(AG23-V23)/(V23-AK23),"") | AO23: =IF(W23<100,"DUST: clean up",IF(V23<AK23,"REVIEW: below support / max loss",IF(AND(N(Q23)>0,V23>=AH23),"SELL 2nd TRIM, trail the rest",IF(AND(N(Q23)>0,V23>=AG23),"TRIM 1/3 + thesis re-check",IF(AA23>IF(ISNUMBER(SEARCH("Lev",C23)),Inputs!$B$15,Inputs!$B$14),"OVERWEIGHT: trim to cap",IF(IF(ISNUMBER(U23),AND(U23>Inputs!$B$5,U23-Inputs!$B$5<=Inputs!$B$16),FALSE),"HOLD: earnings soon",IF(N(Q23)=0,"HOLD: no target","HOLD"))))))) | AP23: =IFERROR(INDEX('Rank Calc'!$P$5:$P$53,MATCH($A23,'Rank Calc'!$A$5:$A$53,0)),"") | AQ23: Fractional leftover (~$30).
A24: QQQ | B24: Invesco QQQ | C24: ETF | D24: Nasdaq-100 | E24: 0.04204 | F24: 713.61 | G24: 715.34 | H24: 702.61 | I24: 725.61 | J24: 679.22 | K24: 700 | L24: 762.86 | M24: 762.86 | R24: n/a | S24: n/a | T24: N/A | U24: n/a | V24: =IF(AND(Inputs!$B$6="After-hours",N(H24)>0),H24,G24) | W24: =E24*V24 | X24: =E24*F24 | Y24: =W24-X24 | Z24: =IFERROR(Y24/X24,"") | AA24: =W24/$W$27 | AB24: =IFERROR(IF(N(H24)>0,H24/G24-1,""),"") | AC24: =IFERROR(V24/I24-1,"") | AD24: =IFERROR(V24/J24-1,"") | AE24: =IFERROR(V24/M24-1,"") | AF24: =IF(N(Q24)>0,Q24/V24-1,"") | AG24: =IF(N(Q24)>0,Q24*Inputs!$B$7,"") | AH24: =IF(N(Q24)>0,Q24*(1+Inputs!$B$8),"") | AI24: =E24*Inputs!$B$9 | AJ24: =IF(N(AG24)>0,AI24*AG24,"") | AK24: =MAX(K24*(1-Inputs!$B$10),F24*(1-IF(ISNUMBER(SEARCH("Lev",C24)),Inputs!$B$12,Inputs!$B$11))) | AL24: =IFERROR(V24/AK24-1,"") | AM24: =IF(V24>=F24/(1-Inputs!$B$13),MAX(F24,L24*(1-Inputs!$B$13)),"not green yet") | AN24: =IF(AND(N(Q24)>0,V24>AK24,AG24>V24),(AG24-V24)/(V24-AK24),"") | AO24: =IF(W24<100,"DUST: clean up",IF(V24<AK24,"REVIEW: below support / max loss",IF(AND(N(Q24)>0,V24>=AH24),"SELL 2nd TRIM, trail the rest",IF(AND(N(Q24)>0,V24>=AG24),"TRIM 1/3 + thesis re-check",IF(AA24>IF(ISNUMBER(SEARCH("Lev",C24)),Inputs!$B$15,Inputs!$B$14),"OVERWEIGHT: trim to cap",IF(IF(ISNUMBER(U24),AND(U24>Inputs!$B$5,U24-Inputs!$B$5<=Inputs!$B$16),FALSE),"HOLD: earnings soon",IF(N(Q24)=0,"HOLD: no target","HOLD"))))))) | AP24: =IFERROR(INDEX('Rank Calc'!$P$5:$P$53,MATCH($A24,'Rank Calc'!$A$5:$A$53,0)),"") | AQ24: Fractional leftover (~$30).
A25: HOOD | B25: Robinhood Markets | C25: Stock | D25: Brokerage | E25: 0.010482 | F25: 90.63 | G25: 91.59 | H25: 87.37 | I25: 108.69 | J25: 92.76 | K25: 89.15 | L25: 126.74 | M25: 150.47 | O25: 133.63 | P25: 145 | Q25: 139.31 | R25: MED | S25: n/a | T25: DISRUPTOR | U25: n/a | V25: =IF(AND(Inputs!$B$6="After-hours",N(H25)>0),H25,G25) | W25: =E25*V25 | X25: =E25*F25 | Y25: =W25-X25 | Z25: =IFERROR(Y25/X25,"") | AA25: =W25/$W$27 | AB25: =IFERROR(IF(N(H25)>0,H25/G25-1,""),"") | AC25: =IFERROR(V25/I25-1,"") | AD25: =IFERROR(V25/J25-1,"") | AE25: =IFERROR(V25/M25-1,"") | AF25: =IF(N(Q25)>0,Q25/V25-1,"") | AG25: =IF(N(Q25)>0,Q25*Inputs!$B$7,"") | AH25: =IF(N(Q25)>0,Q25*(1+Inputs!$B$8),"") | AI25: =E25*Inputs!$B$9 | AJ25: =IF(N(AG25)>0,AI25*AG25,"") | AK25: =MAX(K25*(1-Inputs!$B$10),F25*(1-IF(ISNUMBER(SEARCH("Lev",C25)),Inputs!$B$12,Inputs!$B$11))) | AL25: =IFERROR(V25/AK25-1,"") | AM25: =IF(V25>=F25/(1-Inputs!$B$13),MAX(F25,L25*(1-Inputs!$B$13)),"not green yet") | AN25: =IF(AND(N(Q25)>0,V25>AK25,AG25>V25),(AG25-V25)/(V25-AK25),"") | AO25: =IF(W25<100,"DUST: clean up",IF(V25<AK25,"REVIEW: below support / max loss",IF(AND(N(Q25)>0,V25>=AH25),"SELL 2nd TRIM, trail the rest",IF(AND(N(Q25)>0,V25>=AG25),"TRIM 1/3 + thesis re-check",IF(AA25>IF(ISNUMBER(SEARCH("Lev",C25)),Inputs!$B$15,Inputs!$B$14),"OVERWEIGHT: trim to cap",IF(IF(ISNUMBER(U25),AND(U25>Inputs!$B$5,U25-Inputs!$B$5<=Inputs!$B$16),FALSE),"HOLD: earnings soon",IF(N(Q25)=0,"HOLD: no target","HOLD"))))))) | AP25: =IFERROR(INDEX('Rank Calc'!$P$5:$P$53,MATCH($A25,'Rank Calc'!$A$5:$A$53,0)),"") | AQ25: Fractional leftover (<$1).
A27: TOTAL | W27: =SUM(W6:W25) | X27: =SUM(X6:X25) | Y27: =SUM(Y6:Y25) | Z27: =Y27/X27 | AA27: =SUM(AA6:AA25) | AF27: =SUMPRODUCT(--(Q6:Q25>0),E6:E25,Q6:Q25)/SUMPRODUCT(--(Q6:Q25>0),W6:W25)-1 | AJ27: =SUM(AJ6:AJ25) | AO27: =COUNTIF(AO6:AO25,"REVIEW*")&" review, "&COUNTIF(AO6:AO25,"OVERWEIGHT*")&" overweight, "&COUNTIF(AO6:AO25,"TRIM*")&" trim"

Sheet Watchlist
A1: Joint Watchlist - Quality @ 200-day Buy Zone, Re-buy Watch, New Industries
A2: Ordered by pre-breakout chart setup (most pulled back first). Blue = inputs (10/29 close), green headers = formulas. A status is a prompt to research, never a buy order.
A4: Symbol | B4: Company | C4: List | D4: Held? | E4: Quality Grade | F4: Quality Rank | G4: Chart Setup | H4: Valuation | I4: Disruption | J4: Price | K4: 50-day SMA | L4: 200-day SMA | M4: Analyst Mean Target | N4: # Buy | O4: # Hold | P4: # Sell | Q4: Next Earnings | R4: Wash-Sale Clear | S4: vs 200-day | T4: vs 50-day | U4: Buy Zone Low | V4: Buy Zone High | W4: BUY TARGET | X4: Distance to Buy Target | Y4: Upside: Buy Tgt to Analyst | Z4: WATCH REVIEW LEVEL | AA4: Reward : Risk at Buy Tgt | AB4: % Buy Ratings | AC4: STATUS | AD4: RANK | AE4: Notes
A5: AEM | B5: Agnico Eagle Mines | C5: Buy Zone | E5: A+ | F5: 3 | G5: 86 COILED | H5: RICH -15% (low) | I5: STABLE | J5: 175.92 | K5: 193.8 | L5: 189.53 | M5: 225.4 | N5: 19 | O5: 4 | P5: 1 | Q5: n/a | S5: =J5/L5-1 | T5: =J5/K5-1 | U5: =L5*(1+Inputs!$B$17) | V5: =L5*(1+Inputs!$B$18) | W5: =L5*(1+Inputs!$B$19) | X5: =J5/W5-1 | Y5: =IF(N(M5)>0,M5/W5-1,"") | Z5: =U5 | AA5: =IFERROR(IF(N(M5)>W5,(M5-W5)/(W5-Z5),""),"") | AB5: =IFERROR(N5/(N5+O5+P5),"") | AC5: =IF(D5="HELD","HELD: see Holdings sheet",IF(IF(ISNUMBER(R5),Inputs!$B$5<R5,FALSE),"WASH-SALE LOCK until "&TEXT(R5,"m/d"),IF(J5<U5,"BELOW ZONE: wait for 200-day reclaim",IF(J5>V5,"ABOVE ZONE: extended, wait",IF(IF(ISNUMBER(Q5),AND(Q5>Inputs!$B$5,Q5-Inputs!$B$5<=Inputs!$B$16),FALSE),"IN ZONE: earnings soon, wait",IF(N(M5)<=J5,"IN ZONE: analysts see no upside",IF(J5<=W5,"IN ZONE: at/below buy target - research","IN ZONE: research"))))))) | AD5: =IFERROR(INDEX('Rank Calc'!$P$5:$P$53,MATCH($A5,'Rank Calc'!$A$5:$A$53,0)),"") | AE5: Falling wedge forming; tracks gold.
A6: NVDA | B6: NVIDIA | C6: Buy Zone | E6: A+ | F6: 1 | G6: 71 COILED | H6: FAIR +7% (med) | I6: DISRUPTOR | J6: 213.66 | K6: 221.99 | L6: 204.28 | M6: 334.45 | N6: 69 | O6: 2 | P6: 1 | Q6: 46343 | S6: =J6/L6-1 | T6: =J6/K6-1 | U6: =L6*(1+Inputs!$B$17) | V6: =L6*(1+Inputs!$B$18) | W6: =L6*(1+Inputs!$B$19) | X6: =J6/W6-1 | Y6: =IF(N(M6)>0,M6/W6-1,"") | Z6: =U6 | AA6: =IFERROR(IF(N(M6)>W6,(M6-W6)/(W6-Z6),""),"") | AB6: =IFERROR(N6/(N6+O6+P6),"") | AC6: =IF(D6="HELD","HELD: see Holdings sheet",IF(IF(ISNUMBER(R6),Inputs!$B$5<R6,FALSE),"WASH-SALE LOCK until "&TEXT(R6,"m/d"),IF(J6<U6,"BELOW ZONE: wait for 200-day reclaim",IF(J6>V6,"ABOVE ZONE: extended, wait",IF(IF(ISNUMBER(Q6),AND(Q6>Inputs!$B$5,Q6-Inputs!$B$5<=Inputs!$B$16),FALSE),"IN ZONE: earnings soon, wait",IF(N(M6)<=J6,"IN ZONE: analysts see no upside",IF(J6<=W6,"IN ZONE: at/below buy target - research","IN ZONE: research"))))))) | AD6: =IFERROR(INDEX('Rank Calc'!$P$5:$P$53,MATCH($A6,'Rank Calc'!$A$5:$A$53,0)),"") | AE6: #1 on business quality.
A7: STX | B7: Seagate | C7: Buy Zone | E7: A+ | F7: 4 | G7: 71 COILED | H7: EXPENSIVE -50% (low) | I7: INNOVATING | J7: 700.47 | K7: 803.15 | L7: 690.92 | M7: 1062.55 | N7: 25 | O7: 5 | P7: 0 | Q7: n/a | S7: =J7/L7-1 | T7: =J7/K7-1 | U7: =L7*(1+Inputs!$B$17) | V7: =L7*(1+Inputs!$B$18) | W7: =L7*(1+Inputs!$B$19) | X7: =J7/W7-1 | Y7: =IF(N(M7)>0,M7/W7-1,"") | Z7: =U7 | AA7: =IFERROR(IF(N(M7)>W7,(M7-W7)/(W7-Z7),""),"") | AB7: =IFERROR(N7/(N7+O7+P7),"") | AC7: =IF(D7="HELD","HELD: see Holdings sheet",IF(IF(ISNUMBER(R7),Inputs!$B$5<R7,FALSE),"WASH-SALE LOCK until "&TEXT(R7,"m/d"),IF(J7<U7,"BELOW ZONE: wait for 200-day reclaim",IF(J7>V7,"ABOVE ZONE: extended, wait",IF(IF(ISNUMBER(Q7),AND(Q7>Inputs!$B$5,Q7-Inputs!$B$5<=Inputs!$B$16),FALSE),"IN ZONE: earnings soon, wait",IF(N(M7)<=J7,"IN ZONE: analysts see no upside",IF(J7<=W7,"IN ZONE: at/below buy target - research","IN ZONE: research"))))))) | AD7: =IFERROR(INDEX('Rank Calc'!$P$5:$P$53,MATCH($A7,'Rank Calc'!$A$5:$A$53,0)),"") | AE7: Falling wedge forming; -4.1% after hours.
A8: SCCO | B8: Southern Copper | C8: Buy Zone | E8: A+ | F8: 8 | G8: 71 COILED | H8: EXPENSIVE -38% (high) | I8: STABLE | J8: 191.75 | K8: 201.33 | L8: 189.09 | M8: 176.66 | N8: 1 | O8: 8 | P8: 10 | Q8: n/a | S8: =J8/L8-1 | T8: =J8/K8-1 | U8: =L8*(1+Inputs!$B$17) | V8: =L8*(1+Inputs!$B$18) | W8: =L8*(1+Inputs!$B$19) | X8: =J8/W8-1 | Y8: =IF(N(M8)>0,M8/W8-1,"") | Z8: =U8 | AA8: =IFERROR(IF(N(M8)>W8,(M8-W8)/(W8-Z8),""),"") | AB8: =IFERROR(N8/(N8+O8+P8),"") | AC8: =IF(D8="HELD","HELD: see Holdings sheet",IF(IF(ISNUMBER(R8),Inputs!$B$5<R8,FALSE),"WASH-SALE LOCK until "&TEXT(R8,"m/d"),IF(J8<U8,"BELOW ZONE: wait for 200-day reclaim",IF(J8>V8,"ABOVE ZONE: extended, wait",IF(IF(ISNUMBER(Q8),AND(Q8>Inputs!$B$5,Q8-Inputs!$B$5<=Inputs!$B$16),FALSE),"IN ZONE: earnings soon, wait",IF(N(M8)<=J8,"IN ZONE: analysts see no upside",IF(J8<=W8,"IN ZONE: at/below buy target - research","IN ZONE: research"))))))) | AD8: =IFERROR(INDEX('Rank Calc'!$P$5:$P$53,MATCH($A8,'Rank Calc'!$A$5:$A$53,0)),"") | AE8: Analyst mean target is BELOW price; 10 Sells.
A9: FNV | B9: Franco-Nevada | C9: Buy Zone | E9: A | F9: 11 | G9: 71 COILED | H9: FAIR +1% (med) | I9: STABLE | J9: 231.6 | K9: 252.44 | L9: 240.07 | M9: 287.68 | N9: 7 | O9: 3 | P9: 1 | Q9: 46337 | S9: =J9/L9-1 | T9: =J9/K9-1 | U9: =L9*(1+Inputs!$B$17) | V9: =L9*(1+Inputs!$B$18) | W9: =L9*(1+Inputs!$B$19) | X9: =J9/W9-1 | Y9: =IF(N(M9)>0,M9/W9-1,"") | Z9: =U9 | AA9: =IFERROR(IF(N(M9)>W9,(M9-W9)/(W9-Z9),""),"") | AB9: =IFERROR(N9/(N9+O9+P9),"") | AC9: =IF(D9="HELD","HELD: see Holdings sheet",IF(IF(ISNUMBER(R9),Inputs!$B$5<R9,FALSE),"WASH-SALE LOCK until "&TEXT(R9,"m/d"),IF(J9<U9,"BELOW ZONE: wait for 200-day reclaim",IF(J9>V9,"ABOVE ZONE: extended, wait",IF(IF(ISNUMBER(Q9),AND(Q9>Inputs!$B$5,Q9-Inputs!$B$5<=Inputs!$B$16),FALSE),"IN ZONE: earnings soon, wait",IF(N(M9)<=J9,"IN ZONE: analysts see no upside",IF(J9<=W9,"IN ZONE: at/below buy target - research","IN ZONE: research"))))))) | AD9: =IFERROR(INDEX('Rank Calc'!$P$5:$P$53,MATCH($A9,'Rank Calc'!$A$5:$A$53,0)),"") | AE9: Gold royalty.
A10: AVGO | B10: Broadcom | C10: Buy Zone | E10: A+ | F10: 7 | G10: 57 PULLING BACK | H10: EXPENSIVE -49% (med) | I10: DISRUPTOR | J10: 345 | K10: 353.7 | L10: 367.78 | M10: 532.31 | N10: 53 | O10: 2 | P10: 0 | Q10: 46365 | R10: 46348 | S10: =J10/L10-1 | T10: =J10/K10-1 | U10: =L10*(1+Inputs!$B$17) | V10: =L10*(1+Inputs!$B$18) | W10: =L10*(1+Inputs!$B$19) | X10: =J10/W10-1 | Y10: =IF(N(M10)>0,M10/W10-1,"") | Z10: =U10 | AA10: =IFERROR(IF(N(M10)>W10,(M10-W10)/(W10-Z10),""),"") | AB10: =IFERROR(N10/(N10+O10+P10),"") | AC10: =IF(D10="HELD","HELD: see Holdings sheet",IF(IF(ISNUMBER(R10),Inputs!$B$5<R10,FALSE),"WASH-SALE LOCK until "&TEXT(R10,"m/d"),IF(J10<U10,"BELOW ZONE: wait for 200-day reclaim",IF(J10>V10,"ABOVE ZONE: extended, wait",IF(IF(ISNUMBER(Q10),AND(Q10>Inputs!$B$5,Q10-Inputs!$B$5<=Inputs!$B$16),FALSE),"IN ZONE: earnings soon, wait",IF(N(M10)<=J10,"IN ZONE: analysts see no upside",IF(J10<=W10,"IN ZONE: at/below buy target - research","IN ZONE: research"))))))) | AD10: =IFERROR(INDEX('Rank Calc'!$P$5:$P$53,MATCH($A10,'Rank Calc'!$A$5:$A$53,0)),"") | AE10: Falling wedge forming; thesis intact 9/30. -3.7% after hours.
A11: HOOD | B11: Robinhood Markets | C11: Buy Zone | D11: HELD | E11: A | F11: 14 | G11: 57 PULLING BACK | H11: n/a | I11: DISRUPTOR | J11: 91.59 | K11: 108.69 | L11: 92.76 | M11: 133.63 | N11: 30 | O11: 5 | P11: 2 | Q11: n/a | R11: 46354 | S11: =J11/L11-1 | T11: =J11/K11-1 | U11: =L11*(1+Inputs!$B$17) | V11: =L11*(1+Inputs!$B$18) | W11: =L11*(1+Inputs!$B$19) | X11: =J11/W11-1 | Y11: =IF(N(M11)>0,M11/W11-1,"") | Z11: =U11 | AA11: =IFERROR(IF(N(M11)>W11,(M11-W11)/(W11-Z11),""),"") | AB11: =IFERROR(N11/(N11+O11+P11),"") | AC11: =IF(D11="HELD","HELD: see Holdings sheet",IF(IF(ISNUMBER(R11),Inputs!$B$5<R11,FALSE),"WASH-SALE LOCK until "&TEXT(R11,"m/d"),IF(J11<U11,"BELOW ZONE: wait for 200-day reclaim",IF(J11>V11,"ABOVE ZONE: extended, wait",IF(IF(ISNUMBER(Q11),AND(Q11>Inputs!$B$5,Q11-Inputs!$B$5<=Inputs!$B$16),FALSE),"IN ZONE: earnings soon, wait",IF(N(M11)<=J11,"IN ZONE: analysts see no upside",IF(J11<=W11,"IN ZONE: at/below buy target - research","IN ZONE: research"))))))) | AD11: =IFERROR(INDEX('Rank Calc'!$P$5:$P$53,MATCH($A11,'Rank Calc'!$A$5:$A$53,0)),"") | AE11: Fractional leftover (<$1).
A12: NEM | B12: Newmont | C12: Buy Zone | E12: A | F12: 15 | G12: 57 PULLING BACK | H12: RICH -25% (low) | I12: STABLE | J12: 111.8 | K12: 121.1 | L12: 112.49 | M12: 137.61 | N12: 24 | O12: 4 | P12: 2 | Q12: n/a | S12: =J12/L12-1 | T12: =J12/K12-1 | U12: =L12*(1+Inputs!$B$17) | V12: =L12*(1+Inputs!$B$18) | W12: =L12*(1+Inputs!$B$19) | X12: =J12/W12-1 | Y12: =IF(N(M12)>0,M12/W12-1,"") | Z12: =U12 | AA12: =IFERROR(IF(N(M12)>W12,(M12-W12)/(W12-Z12),""),"") | AB12: =IFERROR(N12/(N12+O12+P12),"") | AC12: =IF(D12="HELD","HELD: see Holdings sheet",IF(IF(ISNUMBER(R12),Inputs!$B$5<R12,FALSE),"WASH-SALE LOCK until "&TEXT(R12,"m/d"),IF(J12<U12,"BELOW ZONE: wait for 200-day reclaim",IF(J12>V12,"ABOVE ZONE: extended, wait",IF(IF(ISNUMBER(Q12),AND(Q12>Inputs!$B$5,Q12-Inputs!$B$5<=Inputs!$B$16),FALSE),"IN ZONE: earnings soon, wait",IF(N(M12)<=J12,"IN ZONE: analysts see no upside",IF(J12<=W12,"IN ZONE: at/below buy target - research","IN ZONE: research"))))))) | AD12: =IFERROR(INDEX('Rank Calc'!$P$5:$P$53,MATCH($A12,'Rank Calc'!$A$5:$A$53,0)),"")
A13: ASML | B13: ASML Holding | C13: Buy Zone | E13: A+ | F13: 9 | G13: 43 PULLING BACK | H13: EXPENSIVE -34% (med) | I13: INNOVATING | J13: 1675.7 | K13: 1708.14 | L13: 1595.65 | M13: 2408.5 | N13: 37 | O13: 4 | P13: 2 | Q13: 46414 | S13: =J13/L13-1 | T13: =J13/K13-1 | U13: =L13*(1+Inputs!$B$17) | V13: =L13*(1+Inputs!$B$18) | W13: =L13*(1+Inputs!$B$19) | X13: =J13/W13-1 | Y13: =IF(N(M13)>0,M13/W13-1,"") | Z13: =U13 | AA13: =IFERROR(IF(N(M13)>W13,(M13-W13)/(W13-Z13),""),"") | AB13: =IFERROR(N13/(N13+O13+P13),"") | AC13: =IF(D13="HELD","HELD: see Holdings sheet",IF(IF(ISNUMBER(R13),Inputs!$B$5<R13,FALSE),"WASH-SALE LOCK until "&TEXT(R13,"m/d"),IF(J13<U13,"BELOW ZONE: wait for 200-day reclaim",IF(J13>V13,"ABOVE ZONE: extended, wait",IF(IF(ISNUMBER(Q13),AND(Q13>Inputs!$B$5,Q13-Inputs!$B$5<=Inputs!$B$16),FALSE),"IN ZONE: earnings soon, wait",IF(N(M13)<=J13,"IN ZONE: analysts see no upside",IF(J13<=W13,"IN ZONE: at/below buy target - research","IN ZONE: research"))))))) | AD13: =IFERROR(INDEX('Rank Calc'!$P$5:$P$53,MATCH($A13,'Rank Calc'!$A$5:$A$53,0)),"") | AE13: Double bottom forming; -3.6% after hours.
A14: AMAT | B14: Applied Materials | C14: Buy Zone | E14: A | F14: 17 | G14: 43 PULLING BACK | H14: EXPENSIVE -50% (med) | I14: INNOVATING | J14: 421.66 | K14: 459.67 | L14: 444.04 | M14: 651.64 | N14: 35 | O14: 5 | P14: 0 | Q14: 46338 | S14: =J14/L14-1 | T14: =J14/K14-1 | U14: =L14*(1+Inputs!$B$17) | V14: =L14*(1+Inputs!$B$18) | W14: =L14*(1+Inputs!$B$19) | X14: =J14/W14-1 | Y14: =IF(N(M14)>0,M14/W14-1,"") | Z14: =U14 | AA14: =IFERROR(IF(N(M14)>W14,(M14-W14)/(W14-Z14),""),"") | AB14: =IFERROR(N14/(N14+O14+P14),"") | AC14: =IF(D14="HELD","HELD: see Holdings sheet",IF(IF(ISNUMBER(R14),Inputs!$B$5<R14,FALSE),"WASH-SALE LOCK until "&TEXT(R14,"m/d"),IF(J14<U14,"BELOW ZONE: wait for 200-day reclaim",IF(J14>V14,"ABOVE ZONE: extended, wait",IF(IF(ISNUMBER(Q14),AND(Q14>Inputs!$B$5,Q14-Inputs!$B$5<=Inputs!$B$16),FALSE),"IN ZONE: earnings soon, wait",IF(N(M14)<=J14,"IN ZONE: analysts see no upside",IF(J14<=W14,"IN ZONE: at/below buy target - research","IN ZONE: research"))))))) | AD14: =IFERROR(INDEX('Rank Calc'!$P$5:$P$53,MATCH($A14,'Rank Calc'!$A$5:$A$53,0)),"") | AE14: -4.5% after hours.
